Workbook

Sheet 하나머티리얼즈1
A1: 하나머티리얼즈POR밴드
B3: 연도 | C3: 2021 | D3: 2022 | E3: 2023 | F3: 2024 | G3: 2025 | H3: 2026(E) | I3: 시가총액 | J3: POR | K3: 현재가 | L3: 발행주식수 | N3: 2027(E) | O3: 123000000000 | P3: 시가총액 | Q3: =K4*L4 -> 1091727604800 | R3: 2027(POR) | S3: =Q3/O3 -> 8.8758342
B4: 영업이익 | C4: 82300000000 | D4: 93700000000 | E4: 41300000000 | F4: 43400000000 | G4: 50100000000 | H4: 95700000000 | I4: =L4*K4 -> 1091727604800 | J4: =I4/H4 -> 11.407812 | K4: 55200 | L4: 19777674

Sheet 하나머티리얼즈2
A1: 날짜 | B1: 종가 | C1: 발행주식수 | D1: 시가총액 | E1: 영업이익 | F1: POR | G1: Mean | H1: +1σ | I1: +2σ | J1: -1σ | K1: -2σ | L1: 2027POR
A2: 44200 | B2: 30600 | C2: =하나머티리얼즈1!$L$4 -> 19777674 | D2: =C2*B2 -> 605196824400 | E2: 82300000000 | F2: =D2/E2 -> 7.3535459 | G2: =$O$4 -> 14.715379 | H2: =$O$6 -> 20.377819 | I2: =$O$7 -> 26.040259 | J2: =$O$9 -> 9.0529394 | K2: =$O$10 -> 3.3904995 | L2: =하나머티리얼즈1!$S$3 -> 8.8758342 | N2: Hana Materials Inc (166090) 과거 가격 데이터 - Investing.com
A3: 44201 | B3: 31350 | C3: =하나머티리얼즈1!$L$4 -> 19777674 | D3: =C3*B3 -> 620030079900 | E3: 82300000000 | F3: =D3/E3 -> 7.5337798 | G3: =$O$4 -> 14.715379 | H3: =$O$6 -> 20.377819 | I3: =$O$7 -> 26.040259 | J3: =$O$9 -> 9.0529394 | K3: =$O$10 -> 3.3904995 | L3: =하나머티리얼즈1!$S$3 -> 8.8758342
A4: 44202 | B4: 30950 | C4: =하나머티리얼즈1!$L$4 -> 19777674 | D4: =C4*B4 -> 612119010300 | E4: 82300000000 | F4: =D4/E4 -> 7.437655 | G4: =$O$4 -> 14.715379 | H4: =$O$6 -> 20.377819 | I4: =$O$7 -> 26.040259 | J4: =$O$9 -> 9.0529394 | K4: =$O$10 -> 3.3904995 | L4: =하나머티리얼즈1!$S$3 -> 8.8758342 | N4: Mean | O4: =AVERAGE(F2:F1476) -> 14.715379
A5: 44203 | B5: 30800 | C5: =하나머티리얼즈1!$L$4 -> 19777674 | D5: =C5*B5 -> 609152359200 | E5: 82300000000 | F5: =D5/E5 -> 7.4016083 | G5: =$O$4 -> 14.715379 | H5: =$O$6 -> 20.377819 | I5: =$O$7 -> 26.040259 | J5: =$O$9 -> 9.0529394 | K5: =$O$10 -> 3.3904995 | L5: =하나머티리얼즈1!$S$3 -> 8.8758342 | N5: STDEV | O5: =STDEV(F2:F1476) -> 5.6624399
A6: 44204 | B6: 29650 | C6: =하나머티리얼즈1!$L$4 -> 19777674 | D6: =C6*B6 -> 586408034100 | E6: 82300000000 | F6: =D6/E6 -> 7.1252495 | G6: =$O$4 -> 14.715379 | H6: =$O$6 -> 20.377819 | I6: =$O$7 -> 26.040259 | J6: =$O$9 -> 9.0529394 | K6: =$O$10 -> 3.3904995 | L6: =하나머티리얼즈1!$S$3 -> 8.8758342 | N6: +1σ | O6: =O4+O5 -> 20.377819
A7: 44207 | B7: 29800 | C7: =하나머티리얼즈1!$L$4 -> 19777674 | D7: =C7*B7 -> 589374685200 | E7: 82300000000 | F7: =D7/E7 -> 7.1612963 | G7: =$O$4 -> 14.715379 | H7: =$O$6 -> 20.377819 | I7: =$O$7 -> 26.040259 | J7: =$O$9 -> 9.0529394 | K7: =$O$10 -> 3.3904995 | L7: =하나머티리얼즈1!$S$3 -> 8.8758342 | N7: +2σ | O7: =(O5*2)+O4 -> 26.040259
A8: 44208 | B8: 29750 | C8: =하나머티리얼즈1!$L$4 -> 19777674 | D8: =C8*B8 -> 588385801500 | E8: 82300000000 | F8: =D8/E8 -> 7.1492807 | G8: =$O$4 -> 14.715379 | H8: =$O$6 -> 20.377819 | I8: =$O$7 -> 26.040259 | J8: =$O$9 -> 9.0529394 | K8: =$O$10 -> 3.3904995 | L8: =하나머티리얼즈1!$S$3 -> 8.8758342 | N8: +3σ | O8: =(O5*3)+O4 -> 31.702699
A9: 44209 | B9: 28950 | C9: =하나머티리얼즈1!$L$4 -> 19777674 | D9: =C9*B9 -> 572563662300 | E9: 82300000000 | F9: =D9/E9 -> 6.9570311 | G9: =$O$4 -> 14.715379 | H9: =$O$6 -> 20.377819 | I9: =$O$7 -> 26.040259 | J9: =$O$9 -> 9.0529394 | K9: =$O$10 -> 3.3904995 | L9: =하나머티리얼즈1!$S$3 -> 8.8758342 | N9: -1σ | O9: =O4-O5 -> 9.0529394
A10: 44210 | B10: 28950 | C10: =하나머티리얼즈1!$L$4 -> 19777674 | D10: =C10*B10 -> 572563662300 | E10: 82300000000 | F10: =D10/E10 -> 6.9570311 | G10: =$O$4 -> 14.715379 | H10: =$O$6 -> 20.377819 | I10: =$O$7 -> 26.040259 | J10: =$O$9 -> 9.0529394 | K10: =$O$10 -> 3.3904995 | L10: =하나머티리얼즈1!$S$3 -> 8.8758342 | N10: -2σ | O10: =O4-(O5*2) -> 3.3904995
A11: 44211 | B11: 31200 | C11: =하나머티리얼즈1!$L$4 -> 19777674 | D11: =C11*B11 -> 617063428800 | E11: 82300000000 | F11: =D11/E11 -> 7.497733 | G11: =$O$4 -> 14.715379 | H11: =$O$6 -> 20.377819 | I11: =$O$7 -> 26.040259 | J11: =$O$9 -> 9.0529394 | K11: =$O$10 -> 3.3904995 | L11: =하나머티리얼즈1!$S$3 -> 8.8758342 | N11: -3σ | O11: =O4-(O5*3) -> -2.2719405
A12: 44213 | B12: 31200 | C12: =하나머티리얼즈1!$L$4 -> 19777674 | D12: =C12*B12 -> 617063428800 | E12: 82300000000 | F12: =D12/E12 -> 7.497733 | G12: =$O$4 -> 14.715379 | H12: =$O$6 -> 20.377819 | I12: =$O$7 -> 26.040259 | J12: =$O$9 -> 9.0529394 | K12: =$O$10 -> 3.3904995 | L12: =하나머티리얼즈1!$S$3 -> 8.8758342
A13: 44214 | B13: 31050 | C13: =하나머티리얼즈1!$L$4 -> 19777674 | D13: =C13*B13 -> 614096777700 | E13: 82300000000 | F13: =D13/E13 -> 7.4616862 | G13: =$O$4 -> 14.715379 | H13: =$O$6 -> 20.377819 | I13: =$O$7 -> 26.040259 | J13: =$O$9 -> 9.0529394 | K13: =$O$10 -> 3.3904995 | L13: =하나머티리얼즈1!$S$3 -> 8.8758342
A14: 44215 | B14: 30850 | C14: =하나머티리얼즈1!$L$4 -> 19777674 | D14: =C14*B14 -> 610141242900 | E14: 82300000000 | F14: =D14/E14 -> 7.4136239 | G14: =$O$4 -> 14.715379 | H14: =$O$6 -> 20.377819 | I14: =$O$7 -> 26.040259 | J14: =$O$9 -> 9.0529394 | K14: =$O$10 -> 3.3904995 | L14: =하나머티리얼즈1!$S$3 -> 8.8758342
A15: 44216 | B15: 31500 | C15: =하나머티리얼즈1!$L$4 -> 19777674 | D15: =C15*B15 -> 622996731000 | E15: 82300000000 | F15: =D15/E15 -> 7.5698266 | G15: =$O$4 -> 14.715379 | H15: =$O$6 -> 20.377819 | I15: =$O$7 -> 26.040259 | J15: =$O$9 -> 9.0529394 | K15: =$O$10 -> 3.3904995 | L15: =하나머티리얼즈1!$S$3 -> 8.8758342
A16: 44217 | B16: 31000 | C16: =하나머티리얼즈1!$L$4 -> 19777674 | D16: =C16*B16 -> 613107894000 | E16: 82300000000 | F16: =D16/E16 -> 7.4496706 | G16: =$O$4 -> 14.715379 | H16: =$O$6 -> 20.377819 | I16: =$O$7 -> 26.040259 | J16: =$O$9 -> 9.0529394 | K16: =$O$10 -> 3.3904995 | L16: =하나머티리얼즈1!$S$3 -> 8.8758342
A17: 44218 | B17: 30400 | C17: =하나머티리얼즈1!$L$4 -> 19777674 | D17: =C17*B17 -> 601241289600 | E17: 82300000000 | F17: =D17/E17 -> 7.3054835 | G17: =$O$4 -> 14.715379 | H17: =$O$6 -> 20.377819 | I17: =$O$7 -> 26.040259 | J17: =$O$9 -> 9.0529394 | K17: =$O$10 -> 3.3904995 | L17: =하나머티리얼즈1!$S$3 -> 8.8758342
A18: 44221 | B18: 30550 | C18: =하나머티리얼즈1!$L$4 -> 19777674 | D18: =C18*B18 -> 604207940700 | E18: 82300000000 | F18: =D18/E18 -> 7.3415303 | G18: =$O$4 -> 14.715379 | H18: =$O$6 -> 20.377819 | I18: =$O$7 -> 26.040259 | J18: =$O$9 -> 9.0529394 | K18: =$O$10 -> 3.3904995 | L18: =하나머티리얼즈1!$S$3 -> 8.8758342
A19: 44222 | B19: 30000 | C19: =하나머티리얼즈1!$L$4 -> 19777674 | D19: =C19*B19 -> 593330220000 | E19: 82300000000 | F19: =D19/E19 -> 7.2093587 | G19: =$O$4 -> 14.715379 | H19: =$O$6 -> 20.377819 | I19: =$O$7 -> 26.040259 | J19: =$O$9 -> 9.0529394 | K19: =$O$10 -> 3.3904995 | L19: =하나머티리얼즈1!$S$3 -> 8.8758342
A20: 44223 | B20: 29150 | C20: =하나머티리얼즈1!$L$4 -> 19777674 | D20: =C20*B20 -> 576519197100 | E20: 82300000000 | F20: =D20/E20 -> 7.0050935 | G20: =$O$4 -> 14.715379 | H20: =$O$6 -> 20.377819 | I20: =$O$7 -> 26.040259 | J20: =$O$9 -> 9.0529394 | K20: =$O$10 -> 3.3904995 | L20: =하나머티리얼즈1!$S$3 -> 8.8758342
A21: 44224 | B21: 27950 | C21: =하나머티리얼즈1!$L$4 -> 19777674 | D21: =C21*B21 -> 552785988300 | E21: 82300000000 | F21: =D21/E21 -> 6.7167192 | G21: =$O$4 -> 14.715379 | H21: =$O$6 -> 20.377819 | I21: =$O$7 -> 26.040259 | J21: =$O$9 -> 9.0529394 | K21: =$O$10 -> 3.3904995 | L21: =하나머티리얼즈1!$S$3 -> 8.8758342
A22: 44225 | B22: 27000 | C22: =하나머티리얼즈1!$L$4 -> 19777674 | D22: =C22*B22 -> 533997198000 | E22: 82300000000 | F22: =D22/E22 -> 6.4884228 | G22: =$O$4 -> 14.715379 | H22: =$O$6 -> 20.377819 | I22: =$O$7 -> 26.040259 | J22: =$O$9 -> 9.0529394 | K22: =$O$10 -> 3.3904995 | L22: =하나머티리얼즈1!$S$3 -> 8.8758342
A23: 44227 | B23: 27000 | C23: =하나머티리얼즈1!$L$4 -> 19777674 | D23: =C23*B23 -> 533997198000 | E23: 82300000000 | F23: =D23/E23 -> 6.4884228 | G23: =$O$4 -> 14.715379 | H23: =$O$6 -> 20.377819 | I23: =$O$7 -> 26.040259 | J23: =$O$9 -> 9.0529394 | K23: =$O$10 -> 3.3904995 | L23: =하나머티리얼즈1!$S$3 -> 8.8758342
... A1474: 46248 | B1474: 58300 | C1474: =하나머티리얼즈1!$L$4 -> 19777674 | D1474: =C1474*B1474 -> 1153038394200 | E1474: 95700000000 | F1474: =D1474/E1474 -> 12.048468 | G1474: =$O$4 -> 14.715379 | H1474: =$O$6 -> 20.377819 | I1474: =$O$7 -> 26.040259 | J1474: =$O$9 -> 9.0529394 | K1474: =$O$10 -> 3.3904995 | L1474: =하나머티리얼즈1!$S$3 -> 8.8758342
A1475: 46252 | B1475: =IFERROR(INDEX(_xlfn.STOCKHISTORY("166090", A1475), 2, 2), "") -> 56500 | C1475: =하나머티리얼즈1!$L$4 -> 19777674 | D1475: =C1475*N(B1475) -> 1117438581000 | E1475: 95700000000 | F1475: =D1475/E1475 -> 11.676474 | G1475: =$O$4 -> 14.715379 | H1475: =$O$6 -> 20.377819 | I1475: =$O$7 -> 26.040259 | J1475: =$O$9 -> 9.0529394 | K1475: =$O$10 -> 3.3904995 | L1475: =하나머티리얼즈1!$S$3 -> 8.8758342
A1476: 46253 | B1476: =IFERROR(INDEX(_xlfn.STOCKHISTORY("166090", A1476), 2, 2), "") | C1476: =하나머티리얼즈1!$L$4 -> 19777674 | D1476: =C1476*N(B1476) -> 0 | E1476: 95700000001 | F1476: =D1476/E1476 -> 0 | G1476: =$O$4 -> 14.715379 | H1476: =$O$6 -> 20.377819 | I1476: =$O$7 -> 26.040259 | J1476: =$O$9 -> 9.0529394 | K1476: =$O$10 -> 3.3904995 | L1476: =하나머티리얼즈1!$S$3 -> 8.8758342
A1477: 46254 | B1477: =IFERROR(INDEX(_xlfn.STOCKHISTORY("166090", A1477), 2, 2), "") | C1477: =하나머티리얼즈1!$L$4 -> 19777674 | D1477: =C1477*N(B1477) -> 0 | E1477: 95700000002 | F1477: =D1477/E1477 -> 0 | G1477: =$O$4 -> 14.715379 | H1477: =$O$6 -> 20.377819 | I1477: =$O$7 -> 26.040259 | J1477: =$O$9 -> 9.0529394 | K1477: =$O$10 -> 3.3904995 | L1477: =하나머티리얼즈1!$S$3 -> 8.8758342
A1478: 46255 | B1478: =IFERROR(INDEX(_xlfn.STOCKHISTORY("166090", A1478), 2, 2), "") | C1478: =하나머티리얼즈1!$L$4 -> 19777674 | D1478: =C1478*N(B1478) -> 0 | E1478: 95700000003 | F1478: =D1478/E1478 -> 0 | G1478: =$O$4 -> 14.715379 | H1478: =$O$6 -> 20.377819 | I1478: =$O$7 -> 26.040259 | J1478: =$O$9 -> 9.0529394 | K1478: =$O$10 -> 3.3904995 | L1478: =하나머티리얼즈1!$S$3 -> 8.8758342
A1479: 46256 | B1479: =IFERROR(INDEX(_xlfn.STOCKHISTORY("166090", A1479), 2, 2), "") | C1479: =하나머티리얼즈1!$L$4 -> 19777674 | D1479: =C1479*N(B1479) -> 0 | E1479: 95700000004 | F1479: =D1479/E1479 -> 0 | G1479: =$O$4 -> 14.715379 | H1479: =$O$6 -> 20.377819 | I1479: =$O$7 -> 26.040259 | J1479: =$O$9 -> 9.0529394 | K1479: =$O$10 -> 3.3904995 | L1479: =하나머티리얼즈1!$S$3 -> 8.8758342
A1480: 46257 | B1480: =IFERROR(INDEX(_xlfn.STOCKHISTORY("166090", A1480), 2, 2), "") | C1480: =하나머티리얼즈1!$L$4 -> 19777674 | D1480: =C1480*N(B1480) -> 0 | E1480: 95700000005 | F1480: =D1480/E1480 -> 0 | G1480: =$O$4 -> 14.715379 | H1480: =$O$6 -> 20.377819 | I1480: =$O$7 -> 26.040259 | J1480: =$O$9 -> 9.0529394 | K1480: =$O$10 -> 3.3904995 | L1480: =하나머티리얼즈1!$S$3 -> 8.8758342
A1481: 46258 | B1481: =IFERROR(INDEX(_xlfn.STOCKHISTORY("166090", A1481), 2, 2), "") | C1481: =하나머티리얼즈1!$L$4 -> 19777674 | D1481: =C1481*N(B1481) -> 0 | E1481: 95700000006 | F1481: =D1481/E1481 -> 0 | G1481: =$O$4 -> 14.715379 | H1481: =$O$6 -> 20.377819 | I1481: =$O$7 -> 26.040259 | J1481: =$O$9 -> 9.0529394 | K1481: =$O$10 -> 3.3904995 | L1481: =하나머티리얼즈1!$S$3 -> 8.8758342
A1482: 46259 | B1482: =IFERROR(INDEX(_xlfn.STOCKHISTORY("166090", A1482), 2, 2), "") | C1482: =하나머티리얼즈1!$L$4 -> 19777674 | D1482: =C1482*N(B1482) -> 0 | E1482: 95700000007 | F1482: =D1482/E1482 -> 0 | G1482: =$O$4 -> 14.715379 | H1482: =$O$6 -> 20.377819 | I1482: =$O$7 -> 26.040259 | J1482: =$O$9 -> 9.0529394 | K1482: =$O$10 -> 3.3904995 | L1482: =하나머티리얼즈1!$S$3 -> 8.8758342
A1483: 46260 | B1483: =IFERROR(INDEX(_xlfn.STOCKHISTORY("166090", A1483), 2, 2), "") | C1483: =하나머티리얼즈1!$L$4 -> 19777674 | D1483: =C1483*N(B1483) -> 0 | E1483: 95700000008 | F1483: =D1483/E1483 -> 0 | G1483: =$O$4 -> 14.715379 | H1483: =$O$6 -> 20.377819 | I1483: =$O$7 -> 26.040259 | J1483: =$O$9 -> 9.0529394 | K1483: =$O$10 -> 3.3904995 | L1483: =하나머티리얼즈1!$S$3 -> 8.8758342
A1484: 46261 | B1484: =IFERROR(INDEX(_xlfn.STOCKHISTORY("166090", A1484), 2, 2), "") | C1484: =하나머티리얼즈1!$L$4 -> 19777674 | D1484: =C1484*N(B1484) -> 0 | E1484: 95700000009 | F1484: =D1484/E1484 -> 0 | G1484: =$O$4 -> 14.715379 | H1484: =$O$6 -> 20.377819 | I1484: =$O$7 -> 26.040259 | J1484: =$O$9 -> 9.0529394 | K1484: =$O$10 -> 3.3904995 | L1484: =하나머티리얼즈1!$S$3 -> 8.8758342
A1485: 46262 | B1485: =IFERROR(INDEX(_xlfn.STOCKHISTORY("166090", A1485), 2, 2), "") | C1485: =하나머티리얼즈1!$L$4 -> 19777674 | D1485: =C1485*N(B1485) -> 0 | E1485: 95700000010 | F1485: =D1485/E1485 -> 0 | G1485: =$O$4 -> 14.715379 | H1485: =$O$6 -> 20.377819 | I1485: =$O$7 -> 26.040259 | J1485: =$O$9 -> 9.0529394 | K1485: =$O$10 -> 3.3904995 | L1485: =하나머티리얼즈1!$S$3 -> 8.8758342
A1486: 46263 | B1486: =IFERROR(INDEX(_xlfn.STOCKHISTORY("166090", A1486), 2, 2), "") | C1486: =하나머티리얼즈1!$L$4 -> 19777674 | D1486: =C1486*N(B1486) -> 0 | E1486: 95700000011 | F1486: =D1486/E1486 -> 0 | G1486: =$O$4 -> 14.715379 | H1486: =$O$6 -> 20.377819 | I1486: =$O$7 -> 26.040259 | J1486: =$O$9 -> 9.0529394 | K1486: =$O$10 -> 3.3904995 | L1486: =하나머티리얼즈1!$S$3 -> 8.8758342
... A1494: 46271 | B1494: =IFERROR(INDEX(_xlfn.STOCKHISTORY("166090", A1494), 2, 2), "") | C1494: =하나머티리얼즈1!$L$4 -> 19777674 | D1494: =C1494*N(B1494) -> 0 | E1494: 95700000019 | F1494: =D1494/E1494 -> 0 | G1494: =$O$4 -> 14.715379 | H1494: =$O$6 -> 20.377819 | I1494: =$O$7 -> 26.040259 | J1494: =$O$9 -> 9.0529394 | K1494: =$O$10 -> 3.3904995 | L1494: =하나머티리얼즈1!$S$3 -> 8.8758342

Sheet 엠케이전자1
A1: 엠케이전자POR밴드
B3: 연도 | C3: 2021 | D3: 2022 | E3: 2023 | F3: 2024 | G3: 2025 | H3: 2026(E) | I3: 시가총액 | J3: POR | K3: 현재가 | L3: 발행주식수 | N3: 2027(E) | O3: 177900000000 | P3: 시가총액 | Q3: =K4*L4 -> 366304215240 | R3: 2027(POR) | S3: =Q3/O3 -> 2.0590456
B4: 영업이익 | C4: 108500000000 | D4: 80300000000 | E4: 46500000000 | F4: 56100000000 | G4: 14200000000 | H4: 114800000000 | I4: =L4*K4 -> 366304215240 | J4: =I4/H4 -> 3.1908033 | K4: 15140 | L4: 24194466

Sheet 엠케이전자2
A1: 날짜 | B1: 종가 | C1: 발행주식수 | D1: 시가총액 | E1: 영업이익 | F1: POR | G1: Mean | H1: +1σ | I1: +2σ | J1: -1σ | K1: -2σ | L1: 2027POR
A2: 44200 | B2: 11400 | C2: =엠케이전자1!$L$4 -> 24194466 | D2: =C2*B2 -> 275816912400 | E2: 108500000000 | F2: =D2/E2 -> 2.5420914 | G2: =$O$4 -> 6.1861404 | H2: =$O$6 -> 10.0133 | I2: =$O$7 -> 13.840459 | J2: =$O$9 -> 2.358981 | K2: =$O$10 -> -1.4681784 | L2: =엠케이전자1!$S$3 -> 2.0590456 | N2: MK Electron (033160) 과거 가격 데이터 - Investing.com
A3: 44201 | B3: 11250 | C3: =엠케이전자1!$L$4 -> 24194466 | D3: =C3*B3 -> 272187742500 | E3: 108500000000 | F3: =D3/E3 -> 2.5086428 | G3: =$O$4 -> 6.1861404 | H3: =$O$6 -> 10.0133 | I3: =$O$7 -> 13.840459 | J3: =$O$9 -> 2.358981 | K3: =$O$10 -> -1.4681784 | L3: =엠케이전자1!$S$3 -> 2.0590456
A4: 44202 | B4: 10900 | C4: =엠케이전자1!$L$4 -> 24194466 | D4: =C4*B4 -> 263719679400 | E4: 108500000000 | F4: =D4/E4 -> 2.4305961 | G4: =$O$4 -> 6.1861404 | H4: =$O$6 -> 10.0133 | I4: =$O$7 -> 13.840459 | J4: =$O$9 -> 2.358981 | K4: =$O$10 -> -1.4681784 | L4: =엠케이전자1!$S$3 -> 2.0590456 | N4: Mean | O4: =AVERAGE(F2:F1470) -> 6.1861404
A5: 44203 | B5: 11000 | C5: =엠케이전자1!$L$4 -> 24194466 | D5: =C5*B5 -> 266139126000 | E5: 108500000000 | F5: =D5/E5 -> 2.4528952 | G5: =$O$4 -> 6.1861404 | H5: =$O$6 -> 10.0133 | I5: =$O$7 -> 13.840459 | J5: =$O$9 -> 2.358981 | K5: =$O$10 -> -1.4681784 | L5: =엠케이전자1!$S$3 -> 2.0590456 | N5: STDEV | O5: =STDEV(F2:F1470) -> 3.8271594
A6: 44204 | B6: 10850 | C6: =엠케이전자1!$L$4 -> 24194466 | D6: =C6*B6 -> 262509956100 | E6: 108500000000 | F6: =D6/E6 -> 2.4194466 | G6: =$O$4 -> 6.1861404 | H6: =$O$6 -> 10.0133 | I6: =$O$7 -> 13.840459 | J6: =$O$9 -> 2.358981 | K6: =$O$10 -> -1.4681784 | L6: =엠케이전자1!$S$3 -> 2.0590456 | N6: +1σ | O6: =O4+O5 -> 10.0133
A7: 44206 | B7: 10850 | C7: =엠케이전자1!$L$4 -> 24194466 | D7: =C7*B7 -> 262509956100 | E7: 108500000000 | F7: =D7/E7 -> 2.4194466 | G7: =$O$4 -> 6.1861404 | H7: =$O$6 -> 10.0133 | I7: =$O$7 -> 13.840459 | J7: =$O$9 -> 2.358981 | K7: =$O$10 -> -1.4681784 | L7: =엠케이전자1!$S$3 -> 2.0590456 | N7: +2σ | O7: =(O5*2)+O4 -> 13.840459
A8: 44207 | B8: 11300 | C8: =엠케이전자1!$L$4 -> 24194466 | D8: =C8*B8 -> 273397465800 | E8: 108500000000 | F8: =D8/E8 -> 2.5197923 | G8: =$O$4 -> 6.1861404 | H8: =$O$6 -> 10.0133 | I8: =$O$7 -> 13.840459 | J8: =$O$9 -> 2.358981 | K8: =$O$10 -> -1.4681784 | L8: =엠케이전자1!$S$3 -> 2.0590456 | N8: +3σ | O8: =(O5*3)+O4 -> 17.667619
A9: 44208 | B9: 10800 | C9: =엠케이전자1!$L$4 -> 24194466 | D9: =C9*B9 -> 261300232800 | E9: 108500000000 | F9: =D9/E9 -> 2.4082971 | G9: =$O$4 -> 6.1861404 | H9: =$O$6 -> 10.0133 | I9: =$O$7 -> 13.840459 | J9: =$O$9 -> 2.358981 | K9: =$O$10 -> -1.4681784 | L9: =엠케이전자1!$S$3 -> 2.0590456 | N9: -1σ | O9: =O4-O5 -> 2.358981
A10: 44209 | B10: 11100 | C10: =엠케이전자1!$L$4 -> 24194466 | D10: =C10*B10 -> 268558572600 | E10: 108500000000 | F10: =D10/E10 -> 2.4751942 | G10: =$O$4 -> 6.1861404 | H10: =$O$6 -> 10.0133 | I10: =$O$7 -> 13.840459 | J10: =$O$9 -> 2.358981 | K10: =$O$10 -> -1.4681784 | L10: =엠케이전자1!$S$3 -> 2.0590456 | N10: -2σ | O10: =O4-(O5*2) -> -1.4681784
A11: 44210 | B11: 11200 | C11: =엠케이전자1!$L$4 -> 24194466 | D11: =C11*B11 -> 270978019200 | E11: 108500000000 | F11: =D11/E11 -> 2.4974933 | G11: =$O$4 -> 6.1861404 | H11: =$O$6 -> 10.0133 | I11: =$O$7 -> 13.840459 | J11: =$O$9 -> 2.358981 | K11: =$O$10 -> -1.4681784 | L11: =엠케이전자1!$S$3 -> 2.0590456 | N11: -3σ | O11: =O4-(O5*3) -> -5.2953378
A12: 44211 | B12: 10850 | C12: =엠케이전자1!$L$4 -> 24194466 | D12: =C12*B12 -> 262509956100 | E12: 108500000000 | F12: =D12/E12 -> 2.4194466 | G12: =$O$4 -> 6.1861404 | H12: =$O$6 -> 10.0133 | I12: =$O$7 -> 13.840459 | J12: =$O$9 -> 2.358981 | K12: =$O$10 -> -1.4681784 | L12: =엠케이전자1!$S$3 -> 2.0590456
A13: 44214 | B13: 10700 | C13: =엠케이전자1!$L$4 -> 24194466 | D13: =C13*B13 -> 258880786200 | E13: 108500000000 | F13: =D13/E13 -> 2.385998 | G13: =$O$4 -> 6.1861404 | H13: =$O$6 -> 10.0133 | I13: =$O$7 -> 13.840459 | J13: =$O$9 -> 2.358981 | K13: =$O$10 -> -1.4681784 | L13: =엠케이전자1!$S$3 -> 2.0590456
A14: 44215 | B14: 11050 | C14: =엠케이전자1!$L$4 -> 24194466 | D14: =C14*B14 -> 267348849300 | E14: 108500000000 | F14: =D14/E14 -> 2.4640447 | G14: =$O$4 -> 6.1861404 | H14: =$O$6 -> 10.0133 | I14: =$O$7 -> 13.840459 | J14: =$O$9 -> 2.358981 | K14: =$O$10 -> -1.4681784 | L14: =엠케이전자1!$S$3 -> 2.0590456
A15: 44216 | B15: 11250 | C15: =엠케이전자1!$L$4 -> 24194466 | D15: =C15*B15 -> 272187742500 | E15: 108500000000 | F15: =D15/E15 -> 2.5086428 | G15: =$O$4 -> 6.1861404 | H15: =$O$6 -> 10.0133 | I15: =$O$7 -> 13.840459 | J15: =$O$9 -> 2.358981 | K15: =$O$10 -> -1.4681784 | L15: =엠케이전자1!$S$3 -> 2.0590456
A16: 44217 | B16: 11600 | C16: =엠케이전자1!$L$4 -> 24194466 | D16: =C16*B16 -> 280655805600 | E16: 108500000000 | F16: =D16/E16 -> 2.5866895 | G16: =$O$4 -> 6.1861404 | H16: =$O$6 -> 10.0133 | I16: =$O$7 -> 13.840459 | J16: =$O$9 -> 2.358981 | K16: =$O$10 -> -1.4681784 | L16: =엠케이전자1!$S$3 -> 2.0590456
A17: 44218 | B17: 11400 | C17: =엠케이전자1!$L$4 -> 24194466 | D17: =C17*B17 -> 275816912400 | E17: 108500000000 | F17: =D17/E17 -> 2.5420914 | G17: =$O$4 -> 6.1861404 | H17: =$O$6 -> 10.0133 | I17: =$O$7 -> 13.840459 | J17: =$O$9 -> 2.358981 | K17: =$O$10 -> -1.4681784 | L17: =엠케이전자1!$S$3 -> 2.0590456
A18: 44220 | B18: 11400 | C18: =엠케이전자1!$L$4 -> 24194466 | D18: =C18*B18 -> 275816912400 | E18: 108500000000 | F18: =D18/E18 -> 2.5420914 | G18: =$O$4 -> 6.1861404 | H18: =$O$6 -> 10.0133 | I18: =$O$7 -> 13.840459 | J18: =$O$9 -> 2.358981 | K18: =$O$10 -> -1.4681784 | L18: =엠케이전자1!$S$3 -> 2.0590456
A19: 44221 | B19: 11700 | C19: =엠케이전자1!$L$4 -> 24194466 | D19: =C19*B19 -> 283075252200 | E19: 108500000000 | F19: =D19/E19 -> 2.6089885 | G19: =$O$4 -> 6.1861404 | H19: =$O$6 -> 10.0133 | I19: =$O$7 -> 13.840459 | J19: =$O$9 -> 2.358981 | K19: =$O$10 -> -1.4681784 | L19: =엠케이전자1!$S$3 -> 2.0590456
A20: 44222 | B20: 11500 | C20: =엠케이전자1!$L$4 -> 24194466 | D20: =C20*B20 -> 278236359000 | E20: 108500000000 | F20: =D20/E20 -> 2.5643904 | G20: =$O$4 -> 6.1861404 | H20: =$O$6 -> 10.0133 | I20: =$O$7 -> 13.840459 | J20: =$O$9 -> 2.358981 | K20: =$O$10 -> -1.4681784 | L20: =엠케이전자1!$S$3 -> 2.0590456
A21: 44223 | B21: 11100 | C21: =엠케이전자1!$L$4 -> 24194466 | D21: =C21*B21 -> 268558572600 | E21: 108500000000 | F21: =D21/E21 -> 2.4751942 | G21: =$O$4 -> 6.1861404 | H21: =$O$6 -> 10.0133 | I21: =$O$7 -> 13.840459 | J21: =$O$9 -> 2.358981 | K21: =$O$10 -> -1.4681784 | L21: =엠케이전자1!$S$3 -> 2.0590456
A22: 44224 | B22: 10650 | C22: =엠케이전자1!$L$4 -> 24194466 | D22: =C22*B22 -> 257671062900 | E22: 108500000000 | F22: =D22/E22 -> 2.3748485 | G22: =$O$4 -> 6.1861404 | H22: =$O$6 -> 10.0133 | I22: =$O$7 -> 13.840459 | J22: =$O$9 -> 2.358981 | K22: =$O$10 -> -1.4681784 | L22: =엠케이전자1!$S$3 -> 2.0590456
A23: 44225 | B23: 10400 | C23: =엠케이전자1!$L$4 -> 24194466 | D23: =C23*B23 -> 251622446400 | E23: 108500000000 | F23: =D23/E23 -> 2.3191009 | G23: =$O$4 -> 6.1861404 | H23: =$O$6 -> 10.0133 | I23: =$O$7 -> 13.840459 | J23: =$O$9 -> 2.358981 | K23: =$O$10 -> -1.4681784 | L23: =엠케이전자1!$S$3 -> 2.0590456
... A1468: 46248 | B1468: 15800 | C1468: =엠케이전자1!$L$4 -> 24194466 | D1468: =C1468*B1468 -> 382272562800 | E1468: 114800000000 | F1468: =D1468/E1468 -> 3.3299004 | G1468: =$O$4 -> 6.1861404 | H1468: =$O$6 -> 10.0133 | I1468: =$O$7 -> 13.840459 | J1468: =$O$9 -> 2.358981 | K1468: =$O$10 -> -1.4681784 | L1468: =엠케이전자1!$S$3 -> 2.0590456
A1469: 46252 | B1469: =IFERROR(INDEX(_xlfn.STOCKHISTORY("033160", A1469), 2, 2), "") -> 15670 | C1469: =엠케이전자1!$L$4 -> 24194466 | D1469: =C1469*N(B1469) -> 379127282220 | E1469: 114800000000 | F1469: =D1469/E1469 -> 3.3025025 | G1469: =$O$4 -> 6.1861404 | H1469: =$O$6 -> 10.0133 | I1469: =$O$7 -> 13.840459 | J1469: =$O$9 -> 2.358981 | K1469: =$O$10 -> -1.4681784 | L1469: =엠케이전자1!$S$3 -> 2.0590456
A1470: 46253 | B1470: =IFERROR(INDEX(_xlfn.STOCKHISTORY("033160", A1470), 2, 2), "") | C1470: =엠케이전자1!$L$4 -> 24194466 | D1470: =C1470*N(B1470) -> 0 | E1470: 114800000001 | F1470: =D1470/E1470 -> 0 | G1470: =$O$4 -> 6.1861404 | H1470: =$O$6 -> 10.0133 | I1470: =$O$7 -> 13.840459 | J1470: =$O$9 -> 2.358981 | K1470: =$O$10 -> -1.4681784 | L1470: =엠케이전자1!$S$3 -> 2.0590456
A1471: 46254 | B1471: =IFERROR(INDEX(_xlfn.STOCKHISTORY("033160", A1471), 2, 2), "") | C1471: =엠케이전자1!$L$4 -> 24194466 | D1471: =C1471*N(B1471) -> 0 | E1471: 114800000002 | F1471: =D1471/E1471 -> 0 | G1471: =$O$4 -> 6.1861404 | H1471: =$O$6 -> 10.0133 | I1471: =$O$7 -> 13.840459 | J1471: =$O$9 -> 2.358981 | K1471: =$O$10 -> -1.4681784 | L1471: =엠케이전자1!$S$3 -> 2.0590456
A1472: 46255 | B1472: =IFERROR(INDEX(_xlfn.STOCKHISTORY("033160", A1472), 2, 2), "") | C1472: =엠케이전자1!$L$4 -> 24194466 | D1472: =C1472*N(B1472) -> 0 | E1472: 114800000003 | F1472: =D1472/E1472 -> 0 | G1472: =$O$4 -> 6.1861404 | H1472: =$O$6 -> 10.0133 | I1472: =$O$7 -> 13.840459 | J1472: =$O$9 -> 2.358981 | K1472: =$O$10 -> -1.4681784 | L1472: =엠케이전자1!$S$3 -> 2.0590456
A1473: 46256 | B1473: =IFERROR(INDEX(_xlfn.STOCKHISTORY("033160", A1473), 2, 2), "") | C1473: =엠케이전자1!$L$4 -> 24194466 | D1473: =C1473*N(B1473) -> 0 | E1473: 114800000004 | F1473: =D1473/E1473 -> 0 | G1473: =$O$4 -> 6.1861404 | H1473: =$O$6 -> 10.0133 | I1473: =$O$7 -> 13.840459 | J1473: =$O$9 -> 2.358981 | K1473: =$O$10 -> -1.4681784 | L1473: =엠케이전자1!$S$3 -> 2.0590456
A1474: 46257 | B1474: =IFERROR(INDEX(_xlfn.STOCKHISTORY("033160", A1474), 2, 2), "") | C1474: =엠케이전자1!$L$4 -> 24194466 | D1474: =C1474*N(B1474) -> 0 | E1474: 114800000005 | F1474: =D1474/E1474 -> 0 | G1474: =$O$4 -> 6.1861404 | H1474: =$O$6 -> 10.0133 | I1474: =$O$7 -> 13.840459 | J1474: =$O$9 -> 2.358981 | K1474: =$O$10 -> -1.4681784 | L1474: =엠케이전자1!$S$3 -> 2.0590456
A1475: 46258 | B1475: =IFERROR(INDEX(_xlfn.STOCKHISTORY("033160", A1475), 2, 2), "") | C1475: =엠케이전자1!$L$4 -> 24194466 | D1475: =C1475*N(B1475) -> 0 | E1475: 114800000006 | F1475: =D1475/E1475 -> 0 | G1475: =$O$4 -> 6.1861404 | H1475: =$O$6 -> 10.0133 | I1475: =$O$7 -> 13.840459 | J1475: =$O$9 -> 2.358981 | K1475: =$O$10 -> -1.4681784 | L1475: =엠케이전자1!$S$3 -> 2.0590456
A1476: 46259 | B1476: =IFERROR(INDEX(_xlfn.STOCKHISTORY("033160", A1476), 2, 2), "") | C1476: =엠케이전자1!$L$4 -> 24194466 | D1476: =C1476*N(B1476) -> 0 | E1476: 114800000007 | F1476: =D1476/E1476 -> 0 | G1476: =$O$4 -> 6.1861404 | H1476: =$O$6 -> 10.0133 | I1476: =$O$7 -> 13.840459 | J1476: =$O$9 -> 2.358981 | K1476: =$O$10 -> -1.4681784 | L1476: =엠케이전자1!$S$3 -> 2.0590456
A1477: 46260 | B1477: =IFERROR(INDEX(_xlfn.STOCKHISTORY("033160", A1477), 2, 2), "") | C1477: =엠케이전자1!$L$4 -> 24194466 | D1477: =C1477*N(B1477) -> 0 | E1477: 114800000008 | F1477: =D1477/E1477 -> 0 | G1477: =$O$4 -> 6.1861404 | H1477: =$O$6 -> 10.0133 | I1477: =$O$7 -> 13.840459 | J1477: =$O$9 -> 2.358981 | K1477: =$O$10 -> -1.4681784 | L1477: =엠케이전자1!$S$3 -> 2.0590456
A1478: 46261 | B1478: =IFERROR(INDEX(_xlfn.STOCKHISTORY("033160", A1478), 2, 2), "") | C1478: =엠케이전자1!$L$4 -> 24194466 | D1478: =C1478*N(B1478) -> 0 | E1478: 114800000009 | F1478: =D1478/E1478 -> 0 | G1478: =$O$4 -> 6.1861404 | H1478: =$O$6 -> 10.0133 | I1478: =$O$7 -> 13.840459 | J1478: =$O$9 -> 2.358981 | K1478: =$O$10 -> -1.4681784 | L1478: =엠케이전자1!$S$3 -> 2.0590456
A1479: 46262 | B1479: =IFERROR(INDEX(_xlfn.STOCKHISTORY("033160", A1479), 2, 2), "") | C1479: =엠케이전자1!$L$4 -> 24194466 | D1479: =C1479*N(B1479) -> 0 | E1479: 114800000010 | F1479: =D1479/E1479 -> 0 | G1479: =$O$4 -> 6.1861404 | H1479: =$O$6 -> 10.0133 | I1479: =$O$7 -> 13.840459 | J1479: =$O$9 -> 2.358981 | K1479: =$O$10 -> -1.4681784 | L1479: =엠케이전자1!$S$3 -> 2.0590456
A1480: 46263 | B1480: =IFERROR(INDEX(_xlfn.STOCKHISTORY("033160", A1480), 2, 2), "") | C1480: =엠케이전자1!$L$4 -> 24194466 | D1480: =C1480*N(B1480) -> 0 | E1480: 114800000011 | F1480: =D1480/E1480 -> 0 | G1480: =$O$4 -> 6.1861404 | H1480: =$O$6 -> 10.0133 | I1480: =$O$7 -> 13.840459 | J1480: =$O$9 -> 2.358981 | K1480: =$O$10 -> -1.4681784 | L1480: =엠케이전자1!$S$3 -> 2.0590456
... A1651: 46434 | B1651: =IFERROR(INDEX(_xlfn.STOCKHISTORY("033160", A1651), 2, 2), "") | C1651: =엠케이전자1!$L$4 -> 24194466 | D1651: =C1651*N(B1651) -> 0 | E1651: 114800000182 | F1651: =D1651/E1651 -> 0 | G1651: =$O$4 -> 6.1861404 | H1651: =$O$6 -> 10.0133 | I1651: =$O$7 -> 13.840459 | J1651: =$O$9 -> 2.358981 | K1651: =$O$10 -> -1.4681784 | L1651: =엠케이전자1!$S$3 -> 2.0590456

Sheet 티엘비1
A1: 티엘비POR밴드
B3: 연도 | C3: 2021 | D3: 2022 | E3: 2023 | F3: 2024 | G3: 2025 | H3: 2026(E) | I3: 시가총액 | J3: POR | K3: 현재가 | L3: 발행주식수 | N3: 2027(E) | O3: 81000000000 | P3: 시가총액 | Q3: =K4*L4 -> 802287651000 | R3: 2027(POR) | S3: =Q3/O3 -> 9.9047858
B4: 영업이익 | C4: 13400000000 | D4: 38500000000 | E4: 3000000000 | F4: 3400000000 | G4: 26000000000 | H4: 54400000000 | I4: =L4*K4 -> 802287651000 | J4: =I4/H4 -> 14.747935 | K4: 33850 | L4: 23701260

Sheet 티엘비2
A1: 날짜 | B1: 종가 | C1: 발행주식수 | D1: 시가총액 | E1: 영업이익 | F1: POR | G1: Mean | H1: +1σ | I1: +2σ | J1: -1σ | K1: -2σ | L1: 2027POR
A2: 44200 | B2: 12152 | C2: =티엘비1!$L$4 -> 23701260 | D2: =C2*B2 -> 288017711520 | E2: 13400000000 | F2: =D2/E2 -> 21.493859 | G2: =$O$4 -> 35.205634 | H2: =$O$6 -> 68.217416 | I2: =$O$7 -> 101.2292 | J2: =$O$9 -> 2.193851 | K2: =$O$10 -> -30.817932 | L2: =티엘비1!$S$3 -> 9.9047858 | N2: https://kr.investing.com/equities/tlb-co-historical-data
A3: 44201 | B3: 11878 | C3: =티엘비1!$L$4 -> 23701260 | D3: =C3*B3 -> 281523566280 | E3: 13400000000 | F3: =D3/E3 -> 21.009221 | G3: =$O$4 -> 35.205634 | H3: =$O$6 -> 68.217416 | I3: =$O$7 -> 101.2292 | J3: =$O$9 -> 2.193851 | K3: =$O$10 -> -30.817932 | L3: =티엘비1!$S$3 -> 9.9047858
A4: 44202 | B4: 15441 | C4: =티엘비1!$L$4 -> 23701260 | D4: =C4*B4 -> 365971155660 | E4: 13400000000 | F4: =D4/E4 -> 27.31128 | G4: =$O$4 -> 35.205634 | H4: =$O$6 -> 68.217416 | I4: =$O$7 -> 101.2292 | J4: =$O$9 -> 2.193851 | K4: =$O$10 -> -30.817932 | L4: =티엘비1!$S$3 -> 9.9047858 | N4: Mean | O4: =AVERAGE(F2:F1440) -> 35.205634
A5: 44203 | B5: 14642 | C5: =티엘비1!$L$4 -> 23701260 | D5: =C5*B5 -> 347033848920 | E5: 13400000000 | F5: =D5/E5 -> 25.898048 | G5: =$O$4 -> 35.205634 | H5: =$O$6 -> 68.217416 | I5: =$O$7 -> 101.2292 | J5: =$O$9 -> 2.193851 | K5: =$O$10 -> -30.817932 | L5: =티엘비1!$S$3 -> 9.9047858 | N5: STDEV | O5: =STDEV(F2:F1440) -> 33.011783
A6: 44204 | B6: 13934 | C6: =티엘비1!$L$4 -> 23701260 | D6: =C6*B6 -> 330253356840 | E6: 13400000000 | F6: =D6/E6 -> 24.645773 | G6: =$O$4 -> 35.205634 | H6: =$O$6 -> 68.217416 | I6: =$O$7 -> 101.2292 | J6: =$O$9 -> 2.193851 | K6: =$O$10 -> -30.817932 | L6: =티엘비1!$S$3 -> 9.9047858 | N6: +1σ | O6: =O4+O5 -> 68.217416
A7: 44206 | B7: 13934 | C7: =티엘비1!$L$4 -> 23701260 | D7: =C7*B7 -> 330253356840 | E7: 13400000000 | F7: =D7/E7 -> 24.645773 | G7: =$O$4 -> 35.205634 | H7: =$O$6 -> 68.217416 | I7: =$O$7 -> 101.2292 | J7: =$O$9 -> 2.193851 | K7: =$O$10 -> -30.817932 | L7: =티엘비1!$S$3 -> 9.9047858 | N7: +2σ | O7: =(O5*2)+O4 -> 101.2292
A8: 44207 | B8: 12929 | C8: =티엘비1!$L$4 -> 23701260 | D8: =C8*B8 -> 306433590540 | E8: 13400000000 | F8: =D8/E8 -> 22.868178 | G8: =$O$4 -> 35.205634 | H8: =$O$6 -> 68.217416 | I8: =$O$7 -> 101.2292 | J8: =$O$9 -> 2.193851 | K8: =$O$10 -> -30.817932 | L8: =티엘비1!$S$3 -> 9.9047858 | N8: +3σ | O8: =(O5*3)+O4 -> 134.24098
A9: 44208 | B9: 13545 | C9: =티엘비1!$L$4 -> 23701260 | D9: =C9*B9 -> 321033566700 | E9: 13400000000 | F9: =D9/E9 -> 23.957729 | G9: =$O$4 -> 35.205634 | H9: =$O$6 -> 68.217416 | I9: =$O$7 -> 101.2292 | J9: =$O$9 -> 2.193851 | K9: =$O$10 -> -30.817932 | L9: =티엘비1!$S$3 -> 9.9047858 | N9: -1σ | O9: =O4-O5 -> 2.193851
A10: 44209 | B10: 13043 | C10: =티엘비1!$L$4 -> 23701260 | D10: =C10*B10 -> 309135534180 | E10: 13400000000 | F10: =D10/E10 -> 23.069816 | G10: =$O$4 -> 35.205634 | H10: =$O$6 -> 68.217416 | I10: =$O$7 -> 101.2292 | J10: =$O$9 -> 2.193851 | K10: =$O$10 -> -30.817932 | L10: =티엘비1!$S$3 -> 9.9047858 | N10: -2σ | O10: =O4-(O5*2) -> -30.817932
A11: 44210 | B11: 12655 | C11: =티엘비1!$L$4 -> 23701260 | D11: =C11*B11 -> 299939445300 | E11: 13400000000 | F11: =D11/E11 -> 22.383541 | G11: =$O$4 -> 35.205634 | H11: =$O$6 -> 68.217416 | I11: =$O$7 -> 101.2292 | J11: =$O$9 -> 2.193851 | K11: =$O$10 -> -30.817932 | L11: =티엘비1!$S$3 -> 9.9047858 | N11: -3σ | O11: =O4-(O5*3) -> -63.829714
A12: 44211 | B12: 12632 | C12: =티엘비1!$L$4 -> 23701260 | D12: =C12*B12 -> 299394316320 | E12: 13400000000 | F12: =D12/E12 -> 22.342859 | G12: =$O$4 -> 35.205634 | H12: =$O$6 -> 68.217416 | I12: =$O$7 -> 101.2292 | J12: =$O$9 -> 2.193851 | K12: =$O$10 -> -30.817932 | L12: =티엘비1!$S$3 -> 9.9047858
A13: 44213 | B13: 13934 | C13: =티엘비1!$L$4 -> 23701260 | D13: =C13*B13 -> 330253356840 | E13: 13400000000 | F13: =D13/E13 -> 24.645773 | G13: =$O$4 -> 35.205634 | H13: =$O$6 -> 68.217416 | I13: =$O$7 -> 101.2292 | J13: =$O$9 -> 2.193851 | K13: =$O$10 -> -30.817932 | L13: =티엘비1!$S$3 -> 9.9047858
A14: 44214 | B14: 12175 | C14: =티엘비1!$L$4 -> 23701260 | D14: =C14*B14 -> 288562840500 | E14: 13400000000 | F14: =D14/E14 -> 21.53454 | G14: =$O$4 -> 35.205634 | H14: =$O$6 -> 68.217416 | I14: =$O$7 -> 101.2292 | J14: =$O$9 -> 2.193851 | K14: =$O$10 -> -30.817932 | L14: =티엘비1!$S$3 -> 9.9047858
A15: 44215 | B15: 12106 | C15: =티엘비1!$L$4 -> 23701260 | D15: =C15*B15 -> 286927453560 | E15: 13400000000 | F15: =D15/E15 -> 21.412497 | G15: =$O$4 -> 35.205634 | H15: =$O$6 -> 68.217416 | I15: =$O$7 -> 101.2292 | J15: =$O$9 -> 2.193851 | K15: =$O$10 -> -30.817932 | L15: =티엘비1!$S$3 -> 9.9047858
A16: 44216 | B16: 12312 | C16: =티엘비1!$L$4 -> 23701260 | D16: =C16*B16 -> 291809913120 | E16: 13400000000 | F16: =D16/E16 -> 21.776859 | G16: =$O$4 -> 35.205634 | H16: =$O$6 -> 68.217416 | I16: =$O$7 -> 101.2292 | J16: =$O$9 -> 2.193851 | K16: =$O$10 -> -30.817932 | L16: =티엘비1!$S$3 -> 9.9047858
A17: 44217 | B17: 12746 | C17: =티엘비1!$L$4 -> 23701260 | D17: =C17*B17 -> 302096259960 | E17: 13400000000 | F17: =D17/E17 -> 22.544497 | G17: =$O$4 -> 35.205634 | H17: =$O$6 -> 68.217416 | I17: =$O$7 -> 101.2292 | J17: =$O$9 -> 2.193851 | K17: =$O$10 -> -30.817932 | L17: =티엘비1!$S$3 -> 9.9047858
A18: 44218 | B18: 12792 | C18: =티엘비1!$L$4 -> 23701260 | D18: =C18*B18 -> 303186517920 | E18: 13400000000 | F18: =D18/E18 -> 22.62586 | G18: =$O$4 -> 35.205634 | H18: =$O$6 -> 68.217416 | I18: =$O$7 -> 101.2292 | J18: =$O$9 -> 2.193851 | K18: =$O$10 -> -30.817932 | L18: =티엘비1!$S$3 -> 9.9047858
A19: 44221 | B19: 12792 | C19: =티엘비1!$L$4 -> 23701260 | D19: =C19*B19 -> 303186517920 | E19: 13400000000 | F19: =D19/E19 -> 22.62586 | G19: =$O$4 -> 35.205634 | H19: =$O$6 -> 68.217416 | I19: =$O$7 -> 101.2292 | J19: =$O$9 -> 2.193851 | K19: =$O$10 -> -30.817932 | L19: =티엘비1!$S$3 -> 9.9047858
A20: 44222 | B20: 12381 | C20: =티엘비1!$L$4 -> 23701260 | D20: =C20*B20 -> 293445300060 | E20: 13400000000 | F20: =D20/E20 -> 21.898903 | G20: =$O$4 -> 35.205634 | H20: =$O$6 -> 68.217416 | I20: =$O$7 -> 101.2292 | J20: =$O$9 -> 2.193851 | K20: =$O$10 -> -30.817932 | L20: =티엘비1!$S$3 -> 9.9047858
A21: 44223 | B21: 11924 | C21: =티엘비1!$L$4 -> 23701260 | D21: =C21*B21 -> 282613824240 | E21: 13400000000 | F21: =D21/E21 -> 21.090584 | G21: =$O$4 -> 35.205634 | H21: =$O$6 -> 68.217416 | I21: =$O$7 -> 101.2292 | J21: =$O$9 -> 2.193851 | K21: =$O$10 -> -30.817932 | L21: =티엘비1!$S$3 -> 9.9047858
A22: 44224 | B22: 11650 | C22: =티엘비1!$L$4 -> 23701260 | D22: =C22*B22 -> 276119679000 | E22: 13400000000 | F22: =D22/E22 -> 20.605946 | G22: =$O$4 -> 35.205634 | H22: =$O$6 -> 68.217416 | I22: =$O$7 -> 101.2292 | J22: =$O$9 -> 2.193851 | K22: =$O$10 -> -30.817932 | L22: =티엘비1!$S$3 -> 9.9047858
A23: 44225 | B23: 11136 | C23: =티엘비1!$L$4 -> 23701260 | D23: =C23*B23 -> 263937231360 | E23: 13400000000 | F23: =D23/E23 -> 19.696808 | G23: =$O$4 -> 35.205634 | H23: =$O$6 -> 68.217416 | I23: =$O$7 -> 101.2292 | J23: =$O$9 -> 2.193851 | K23: =$O$10 -> -30.817932 | L23: =티엘비1!$S$3 -> 9.9047858
... A1438: 46248 | B1438: 31400 | C1438: =티엘비1!$L$4 -> 23701260 | D1438: =C1438*B1438 -> 744219564000 | E1438: 54400000000 | F1438: =D1438/E1438 -> 13.680507 | G1438: =$O$4 -> 35.205634 | H1438: =$O$6 -> 68.217416 | I1438: =$O$7 -> 101.2292 | J1438: =$O$9 -> 2.193851 | K1438: =$O$10 -> -30.817932 | L1438: =티엘비1!$S$3 -> 9.9047858
A1439: 46252 | B1439: =IFERROR(INDEX(_xlfn.STOCKHISTORY("356860", A1439), 2, 2), "") -> 34350 | C1439: =티엘비1!$L$4 -> 23701260 | D1439: =C1439*N(B1439) -> 814138281000 | E1439: 54400000000 | F1439: =D1439/E1439 -> 14.965777 | G1439: =$O$4 -> 35.205634 | H1439: =$O$6 -> 68.217416 | I1439: =$O$7 -> 101.2292 | J1439: =$O$9 -> 2.193851 | K1439: =$O$10 -> -30.817932 | L1439: =티엘비1!$S$3 -> 9.9047858
A1440: 46253 | B1440: =IFERROR(INDEX(_xlfn.STOCKHISTORY("356860", A1440), 2, 2), "") | C1440: =티엘비1!$L$4 -> 23701260 | D1440: =C1440*N(B1440) -> 0 | E1440: 54400000000 | F1440: =D1440/E1440 -> 0 | G1440: =$O$4 -> 35.205634 | H1440: =$O$6 -> 68.217416 | I1440: =$O$7 -> 101.2292 | J1440: =$O$9 -> 2.193851 | K1440: =$O$10 -> -30.817932 | L1440: =티엘비1!$S$3 -> 9.9047858
A1441: 46254 | B1441: =IFERROR(INDEX(_xlfn.STOCKHISTORY("356860", A1441), 2, 2), "") | C1441: =티엘비1!$L$4 -> 23701260 | D1441: =C1441*N(B1441) -> 0 | E1441: 54400000001 | F1441: =D1441/E1441 -> 0 | G1441: =$O$4 -> 35.205634 | H1441: =$O$6 -> 68.217416 | I1441: =$O$7 -> 101.2292 | J1441: =$O$9 -> 2.193851 | K1441: =$O$10 -> -30.817932 | L1441: =티엘비1!$S$3 -> 9.9047858
A1442: 46255 | B1442: =IFERROR(INDEX(_xlfn.STOCKHISTORY("356860", A1442), 2, 2), "") | C1442: =티엘비1!$L$4 -> 23701260 | D1442: =C1442*N(B1442) -> 0 | E1442: 54400000002 | F1442: =D1442/E1442 -> 0 | G1442: =$O$4 -> 35.205634 | H1442: =$O$6 -> 68.217416 | I1442: =$O$7 -> 101.2292 | J1442: =$O$9 -> 2.193851 | K1442: =$O$10 -> -30.817932 | L1442: =티엘비1!$S$3 -> 9.9047858
A1443: 46256 | B1443: =IFERROR(INDEX(_xlfn.STOCKHISTORY("356860", A1443), 2, 2), "") | C1443: =티엘비1!$L$4 -> 23701260 | D1443: =C1443*N(B1443) -> 0 | E1443: 54400000003 | F1443: =D1443/E1443 -> 0 | G1443: =$O$4 -> 35.205634 | H1443: =$O$6 -> 68.217416 | I1443: =$O$7 -> 101.2292 | J1443: =$O$9 -> 2.193851 | K1443: =$O$10 -> -30.817932 | L1443: =티엘비1!$S$3 -> 9.9047858
A1444: 46257 | B1444: =IFERROR(INDEX(_xlfn.STOCKHISTORY("356860", A1444), 2, 2), "") | C1444: =티엘비1!$L$4 -> 23701260 | D1444: =C1444*N(B1444) -> 0 | E1444: 54400000004 | F1444: =D1444/E1444 -> 0 | G1444: =$O$4 -> 35.205634 | H1444: =$O$6 -> 68.217416 | I1444: =$O$7 -> 101.2292 | J1444: =$O$9 -> 2.193851 | K1444: =$O$10 -> -30.817932 | L1444: =티엘비1!$S$3 -> 9.9047858
A1445: 46258 | B1445: =IFERROR(INDEX(_xlfn.STOCKHISTORY("356860", A1445), 2, 2), "") | C1445: =티엘비1!$L$4 -> 23701260 | D1445: =C1445*N(B1445) -> 0 | E1445: 54400000005 | F1445: =D1445/E1445 -> 0 | G1445: =$O$4 -> 35.205634 | H1445: =$O$6 -> 68.217416 | I1445: =$O$7 -> 101.2292 | J1445: =$O$9 -> 2.193851 | K1445: =$O$10 -> -30.817932 | L1445: =티엘비1!$S$3 -> 9.9047858
A1446: 46259 | B1446: =IFERROR(INDEX(_xlfn.STOCKHISTORY("356860", A1446), 2, 2), "") | C1446: =티엘비1!$L$4 -> 23701260 | D1446: =C1446*N(B1446) -> 0 | E1446: 54400000006 | F1446: =D1446/E1446 -> 0 | G1446: =$O$4 -> 35.205634 | H1446: =$O$6 -> 68.217416 | I1446: =$O$7 -> 101.2292 | J1446: =$O$9 -> 2.193851 | K1446: =$O$10 -> -30.817932 | L1446: =티엘비1!$S$3 -> 9.9047858
A1447: 46260 | B1447: =IFERROR(INDEX(_xlfn.STOCKHISTORY("356860", A1447), 2, 2), "") | C1447: =티엘비1!$L$4 -> 23701260 | D1447: =C1447*N(B1447) -> 0 | E1447: 54400000007 | F1447: =D1447/E1447 -> 0 | G1447: =$O$4 -> 35.205634 | H1447: =$O$6 -> 68.217416 | I1447: =$O$7 -> 101.2292 | J1447: =$O$9 -> 2.193851 | K1447: =$O$10 -> -30.817932 | L1447: =티엘비1!$S$3 -> 9.9047858
A1448: 46261 | B1448: =IFERROR(INDEX(_xlfn.STOCKHISTORY("356860", A1448), 2, 2), "") | C1448: =티엘비1!$L$4 -> 23701260 | D1448: =C1448*N(B1448) -> 0 | E1448: 54400000008 | F1448: =D1448/E1448 -> 0 | G1448: =$O$4 -> 35.205634 | H1448: =$O$6 -> 68.217416 | I1448: =$O$7 -> 101.2292 | J1448: =$O$9 -> 2.193851 | K1448: =$O$10 -> -30.817932 | L1448: =티엘비1!$S$3 -> 9.9047858

Sheet ISC1
A1: ISC POR밴드
B3: 연도 | C3: 2021 | D3: 2022 | E3: 2023 | F3: 2024 | G3: 2025 | H3: 2026(E) | I3: 시가총액 | J3: POR | K3: 현재가 | L3: 발행주식수 | N3: 2027(E) | O3: 140400000000 | P3: 시가총액 | Q3: =K4*L4 -> 3773076324000 | R3: 2027(POR) | S3: =Q3/O3 -> 26.873763
B4: 영업이익 | C4: 37500000000 | D4: 55900000000 | E4: 10700000000 | F4: 44800000000 | G4: 60100000000 | H4: 102000000000 | I4: =L4*K4 -> 3773076324000 | J4: =I4/H4 -> 36.990944 | K4: 178000 | L4: 21197058

Sheet ISC2
A1: 날짜 | B1: 종가 | C1: 발행주식수 | D1: 시가총액 | E1: 영업이익 | F1: POR | G1: Mean | H1: +1σ | I1: +2σ | J1: -1σ | K1: -2σ | L1: 2027POR
A2: 44200 | B2: 27700 | C2: ='ISC1'!$L$4 -> 21197058 | D2: =C2*B2 -> 587158506600 | E2: 37500000000 | F2: =D2/E2 -> 15.65756 | G2: =$O$4 -> 42.163676 | H2: =$O$6 -> 88.522826 | I2: =$O$7 -> 134.88198 | J2: =$O$9 -> -4.1954743 | K2: =$O$10 -> -50.554625 | L2: ='ISC1'!$S$3 -> 26.873763 | N2: MK Electron (033160) 과거 가격 데이터 - Investing.com
A3: 44201 | B3: 26800 | C3: ='ISC1'!$L$4 -> 21197058 | D3: =C3*B3 -> 568081154400 | E3: 37500000000 | F3: =D3/E3 -> 15.148831 | G3: =$O$4 -> 42.163676 | H3: =$O$6 -> 88.522826 | I3: =$O$7 -> 134.88198 | J3: =$O$9 -> -4.1954743 | K3: =$O$10 -> -50.554625 | L3: ='ISC1'!$S$3 -> 26.873763
A4: 44202 | B4: 25550 | C4: ='ISC1'!$L$4 -> 21197058 | D4: =C4*B4 -> 541584831900 | E4: 37500000000 | F4: =D4/E4 -> 14.442262 | G4: =$O$4 -> 42.163676 | H4: =$O$6 -> 88.522826 | I4: =$O$7 -> 134.88198 | J4: =$O$9 -> -4.1954743 | K4: =$O$10 -> -50.554625 | L4: ='ISC1'!$S$3 -> 26.873763 | N4: Mean | O4: =AVERAGE(F2:F1470) -> 42.163676
A5: 44203 | B5: 25250 | C5: ='ISC1'!$L$4 -> 21197058 | D5: =C5*B5 -> 535225714500 | E5: 37500000000 | F5: =D5/E5 -> 14.272686 | G5: =$O$4 -> 42.163676 | H5: =$O$6 -> 88.522826 | I5: =$O$7 -> 134.88198 | J5: =$O$9 -> -4.1954743 | K5: =$O$10 -> -50.554625 | L5: ='ISC1'!$S$3 -> 26.873763 | N5: STDEV | O5: =STDEV(F2:F1470) -> 46.35915
A6: 44204 | B6: 24350 | C6: ='ISC1'!$L$4 -> 21197058 | D6: =C6*B6 -> 516148362300 | E6: 37500000000 | F6: =D6/E6 -> 13.763956 | G6: =$O$4 -> 42.163676 | H6: =$O$6 -> 88.522826 | I6: =$O$7 -> 134.88198 | J6: =$O$9 -> -4.1954743 | K6: =$O$10 -> -50.554625 | L6: ='ISC1'!$S$3 -> 26.873763 | N6: +1σ | O6: =O4+O5 -> 88.522826
A7: 44206 | B7: 24350 | C7: ='ISC1'!$L$4 -> 21197058 | D7: =C7*B7 -> 516148362300 | E7: 37500000000 | F7: =D7/E7 -> 13.763956 | G7: =$O$4 -> 42.163676 | H7: =$O$6 -> 88.522826 | I7: =$O$7 -> 134.88198 | J7: =$O$9 -> -4.1954743 | K7: =$O$10 -> -50.554625 | L7: ='ISC1'!$S$3 -> 26.873763 | N7: +2σ | O7: =(O5*2)+O4 -> 134.88198
A8: 44207 | B8: 24500 | C8: ='ISC1'!$L$4 -> 21197058 | D8: =C8*B8 -> 519327921000 | E8: 37500000000 | F8: =D8/E8 -> 13.848745 | G8: =$O$4 -> 42.163676 | H8: =$O$6 -> 88.522826 | I8: =$O$7 -> 134.88198 | J8: =$O$9 -> -4.1954743 | K8: =$O$10 -> -50.554625 | L8: ='ISC1'!$S$3 -> 26.873763 | N8: +3σ | O8: =(O5*3)+O4 -> 181.24113
A9: 44208 | B9: 25500 | C9: ='ISC1'!$L$4 -> 21197058 | D9: =C9*B9 -> 540524979000 | E9: 37500000000 | F9: =D9/E9 -> 14.413999 | G9: =$O$4 -> 42.163676 | H9: =$O$6 -> 88.522826 | I9: =$O$7 -> 134.88198 | J9: =$O$9 -> -4.1954743 | K9: =$O$10 -> -50.554625 | L9: ='ISC1'!$S$3 -> 26.873763 | N9: -1σ | O9: =O4-O5 -> -4.1954743
A10: 44209 | B10: 25950 | C10: ='ISC1'!$L$4 -> 21197058 | D10: =C10*B10 -> 550063655100 | E10: 37500000000 | F10: =D10/E10 -> 14.668364 | G10: =$O$4 -> 42.163676 | H10: =$O$6 -> 88.522826 | I10: =$O$7 -> 134.88198 | J10: =$O$9 -> -4.1954743 | K10: =$O$10 -> -50.554625 | L10: ='ISC1'!$S$3 -> 26.873763 | N10: -2σ | O10: =O4-(O5*2) -> -50.554625
A11: 44210 | B11: 26350 | C11: ='ISC1'!$L$4 -> 21197058 | D11: =C11*B11 -> 558542478300 | E11: 37500000000 | F11: =D11/E11 -> 14.894466 | G11: =$O$4 -> 42.163676 | H11: =$O$6 -> 88.522826 | I11: =$O$7 -> 134.88198 | J11: =$O$9 -> -4.1954743 | K11: =$O$10 -> -50.554625 | L11: ='ISC1'!$S$3 -> 26.873763 | N11: -3σ | O11: =O4-(O5*3) -> -96.913775
A12: 44211 | B12: 26300 | C12: ='ISC1'!$L$4 -> 21197058 | D12: =C12*B12 -> 557482625400 | E12: 37500000000 | F12: =D12/E12 -> 14.866203 | G12: =$O$4 -> 42.163676 | H12: =$O$6 -> 88.522826 | I12: =$O$7 -> 134.88198 | J12: =$O$9 -> -4.1954743 | K12: =$O$10 -> -50.554625 | L12: ='ISC1'!$S$3 -> 26.873763
A13: 44213 | B13: 26300 | C13: ='ISC1'!$L$4 -> 21197058 | D13: =C13*B13 -> 557482625400 | E13: 37500000000 | F13: =D13/E13 -> 14.866203 | G13: =$O$4 -> 42.163676 | H13: =$O$6 -> 88.522826 | I13: =$O$7 -> 134.88198 | J13: =$O$9 -> -4.1954743 | K13: =$O$10 -> -50.554625 | L13: ='ISC1'!$S$3 -> 26.873763
A14: 44214 | B14: 26450 | C14: ='ISC1'!$L$4 -> 21197058 | D14: =C14*B14 -> 560662184100 | E14: 37500000000 | F14: =D14/E14 -> 14.950992 | G14: =$O$4 -> 42.163676 | H14: =$O$6 -> 88.522826 | I14: =$O$7 -> 134.88198 | J14: =$O$9 -> -4.1954743 | K14: =$O$10 -> -50.554625 | L14: ='ISC1'!$S$3 -> 26.873763
A15: 44215 | B15: 26350 | C15: ='ISC1'!$L$4 -> 21197058 | D15: =C15*B15 -> 558542478300 | E15: 37500000000 | F15: =D15/E15 -> 14.894466 | G15: =$O$4 -> 42.163676 | H15: =$O$6 -> 88.522826 | I15: =$O$7 -> 134.88198 | J15: =$O$9 -> -4.1954743 | K15: =$O$10 -> -50.554625 | L15: ='ISC1'!$S$3 -> 26.873763
A16: 44216 | B16: 27950 | C16: ='ISC1'!$L$4 -> 21197058 | D16: =C16*B16 -> 592457771100 | E16: 37500000000 | F16: =D16/E16 -> 15.798874 | G16: =$O$4 -> 42.163676 | H16: =$O$6 -> 88.522826 | I16: =$O$7 -> 134.88198 | J16: =$O$9 -> -4.1954743 | K16: =$O$10 -> -50.554625 | L16: ='ISC1'!$S$3 -> 26.873763
A17: 44217 | B17: 28200 | C17: ='ISC1'!$L$4 -> 21197058 | D17: =C17*B17 -> 597757035600 | E17: 37500000000 | F17: =D17/E17 -> 15.940188 | G17: =$O$4 -> 42.163676 | H17: =$O$6 -> 88.522826 | I17: =$O$7 -> 134.88198 | J17: =$O$9 -> -4.1954743 | K17: =$O$10 -> -50.554625 | L17: ='ISC1'!$S$3 -> 26.873763
A18: 44218 | B18: 26850 | C18: ='ISC1'!$L$4 -> 21197058 | D18: =C18*B18 -> 569141007300 | E18: 37500000000 | F18: =D18/E18 -> 15.177094 | G18: =$O$4 -> 42.163676 | H18: =$O$6 -> 88.522826 | I18: =$O$7 -> 134.88198 | J18: =$O$9 -> -4.1954743 | K18: =$O$10 -> -50.554625 | L18: ='ISC1'!$S$3 -> 26.873763
A19: 44220 | B19: 26850 | C19: ='ISC1'!$L$4 -> 21197058 | D19: =C19*B19 -> 569141007300 | E19: 37500000000 | F19: =D19/E19 -> 15.177094 | G19: =$O$4 -> 42.163676 | H19: =$O$6 -> 88.522826 | I19: =$O$7 -> 134.88198 | J19: =$O$9 -> -4.1954743 | K19: =$O$10 -> -50.554625 | L19: ='ISC1'!$S$3 -> 26.873763
A20: 44221 | B20: 26150 | C20: ='ISC1'!$L$4 -> 21197058 | D20: =C20*B20 -> 554303066700 | E20: 37500000000 | F20: =D20/E20 -> 14.781415 | G20: =$O$4 -> 42.163676 | H20: =$O$6 -> 88.522826 | I20: =$O$7 -> 134.88198 | J20: =$O$9 -> -4.1954743 | K20: =$O$10 -> -50.554625 | L20: ='ISC1'!$S$3 -> 26.873763
A21: 44222 | B21: 25650 | C21: ='ISC1'!$L$4 -> 21197058 | D21: =C21*B21 -> 543704537700 | E21: 37500000000 | F21: =D21/E21 -> 14.498788 | G21: =$O$4 -> 42.163676 | H21: =$O$6 -> 88.522826 | I21: =$O$7 -> 134.88198 | J21: =$O$9 -> -4.1954743 | K21: =$O$10 -> -50.554625 | L21: ='ISC1'!$S$3 -> 26.873763
A22: 44223 | B22: 23800 | C22: ='ISC1'!$L$4 -> 21197058 | D22: =C22*B22 -> 504489980400 | E22: 37500000000 | F22: =D22/E22 -> 13.453066 | G22: =$O$4 -> 42.163676 | H22: =$O$6 -> 88.522826 | I22: =$O$7 -> 134.88198 | J22: =$O$9 -> -4.1954743 | K22: =$O$10 -> -50.554625 | L22: ='ISC1'!$S$3 -> 26.873763
A23: 44224 | B23: 22700 | C23: ='ISC1'!$L$4 -> 21197058 | D23: =C23*B23 -> 481173216600 | E23: 37500000000 | F23: =D23/E23 -> 12.831286 | G23: =$O$4 -> 42.163676 | H23: =$O$6 -> 88.522826 | I23: =$O$7 -> 134.88198 | J23: =$O$9 -> -4.1954743 | K23: =$O$10 -> -50.554625 | L23: ='ISC1'!$S$3 -> 26.873763
... A1495: 46248 | B1495: 161300 | C1495: ='ISC1'!$L$4 -> 21197058 | D1495: =C1495*B1495 -> 3419085455400 | E1495: 102000000000 | F1495: =D1495/E1495 -> 33.520446 | G1495: =$O$4 -> 42.163676 | H1495: =$O$6 -> 88.522826 | I1495: =$O$7 -> 134.88198 | J1495: =$O$9 -> -4.1954743 | K1495: =$O$10 -> -50.554625 | L1495: ='ISC1'!$S$3 -> 26.873763
A1496: 46252 | B1496: =IFERROR(INDEX(_xlfn.STOCKHISTORY("095340", A1496), 2, 2), "") -> 167100 | C1496: ='ISC1'!$L$4 -> 21197058 | D1496: =C1496*N(B1496) -> 3542028391800 | E1496: 102000000000 | F1496: =D1496/E1496 -> 34.725769 | G1496: =$O$4 -> 42.163676 | H1496: =$O$6 -> 88.522826 | I1496: =$O$7 -> 134.88198 | J1496: =$O$9 -> -4.1954743 | K1496: =$O$10 -> -50.554625 | L1496: ='ISC1'!$S$3 -> 26.873763
A1497: 46253 | B1497: =IFERROR(INDEX(_xlfn.STOCKHISTORY("095340", A1497), 2, 2), "") | C1497: ='ISC1'!$L$4 -> 21197058 | D1497: =C1497*N(B1497) -> 0 | E1497: 102000000001 | F1497: =D1497/E1497 -> 0 | G1497: =$O$4 -> 42.163676 | H1497: =$O$6 -> 88.522826 | I1497: =$O$7 -> 134.88198 | J1497: =$O$9 -> -4.1954743 | K1497: =$O$10 -> -50.554625 | L1497: ='ISC1'!$S$3 -> 26.873763
A1498: 46254 | B1498: =IFERROR(INDEX(_xlfn.STOCKHISTORY("095340", A1498), 2, 2), "") | C1498: ='ISC1'!$L$4 -> 21197058 | D1498: =C1498*N(B1498) -> 0 | E1498: 102000000002 | F1498: =D1498/E1498 -> 0 | G1498: =$O$4 -> 42.163676 | H1498: =$O$6 -> 88.522826 | I1498: =$O$7 -> 134.88198 | J1498: =$O$9 -> -4.1954743 | K1498: =$O$10 -> -50.554625 | L1498: ='ISC1'!$S$3 -> 26.873763
A1499: 46255 | B1499: =IFERROR(INDEX(_xlfn.STOCKHISTORY("095340", A1499), 2, 2), "") | C1499: ='ISC1'!$L$4 -> 21197058 | D1499: =C1499*N(B1499) -> 0 | E1499: 102000000003 | F1499: =D1499/E1499 -> 0 | G1499: =$O$4 -> 42.163676 | H1499: =$O$6 -> 88.522826 | I1499: =$O$7 -> 134.88198 | J1499: =$O$9 -> -4.1954743 | K1499: =$O$10 -> -50.554625 | L1499: ='ISC1'!$S$3 -> 26.873763
A1500: 46256 | B1500: =IFERROR(INDEX(_xlfn.STOCKHISTORY("095340", A1500), 2, 2), "") | C1500: ='ISC1'!$L$4 -> 21197058 | D1500: =C1500*N(B1500) -> 0 | E1500: 102000000004 | F1500: =D1500/E1500 -> 0 | G1500: =$O$4 -> 42.163676 | H1500: =$O$6 -> 88.522826 | I1500: =$O$7 -> 134.88198 | J1500: =$O$9 -> -4.1954743 | K1500: =$O$10 -> -50.554625 | L1500: ='ISC1'!$S$3 -> 26.873763
A1501: 46257 | B1501: =IFERROR(INDEX(_xlfn.STOCKHISTORY("095340", A1501), 2, 2), "") | C1501: ='ISC1'!$L$4 -> 21197058 | D1501: =C1501*N(B1501) -> 0 | E1501: 102000000005 | F1501: =D1501/E1501 -> 0 | G1501: =$O$4 -> 42.163676 | H1501: =$O$6 -> 88.522826 | I1501: =$O$7 -> 134.88198 | J1501: =$O$9 -> -4.1954743 | K1501: =$O$10 -> -50.554625 | L1501: ='ISC1'!$S$3 -> 26.873763
A1502: 46258 | B1502: =IFERROR(INDEX(_xlfn.STOCKHISTORY("095340", A1502), 2, 2), "") | C1502: ='ISC1'!$L$4 -> 21197058 | D1502: =C1502*N(B1502) -> 0 | E1502: 102000000006 | F1502: =D1502/E1502 -> 0 | G1502: =$O$4 -> 42.163676 | H1502: =$O$6 -> 88.522826 | I1502: =$O$7 -> 134.88198 | J1502: =$O$9 -> -4.1954743 | K1502: =$O$10 -> -50.554625 | L1502: ='ISC1'!$S$3 -> 26.873763
A1503: 46259 | B1503: =IFERROR(INDEX(_xlfn.STOCKHISTORY("095340", A1503), 2, 2), "") | C1503: ='ISC1'!$L$4 -> 21197058 | D1503: =C1503*N(B1503) -> 0 | E1503: 102000000007 | F1503: =D1503/E1503 -> 0 | G1503: =$O$4 -> 42.163676 | H1503: =$O$6 -> 88.522826 | I1503: =$O$7 -> 134.88198 | J1503: =$O$9 -> -4.1954743 | K1503: =$O$10 -> -50.554625 | L1503: ='ISC1'!$S$3 -> 26.873763
A1504: 46260 | B1504: =IFERROR(INDEX(_xlfn.STOCKHISTORY("095340", A1504), 2, 2), "") | C1504: ='ISC1'!$L$4 -> 21197058 | D1504: =C1504*N(B1504) -> 0 | E1504: 102000000008 | F1504: =D1504/E1504 -> 0 | G1504: =$O$4 -> 42.163676 | H1504: =$O$6 -> 88.522826 | I1504: =$O$7 -> 134.88198 | J1504: =$O$9 -> -4.1954743 | K1504: =$O$10 -> -50.554625 | L1504: ='ISC1'!$S$3 -> 26.873763
A1505: 46261 | B1505: =IFERROR(INDEX(_xlfn.STOCKHISTORY("095340", A1505), 2, 2), "") | C1505: ='ISC1'!$L$4 -> 21197058 | D1505: =C1505*N(B1505) -> 0 | E1505: 102000000009 | F1505: =D1505/E1505 -> 0 | G1505: =$O$4 -> 42.163676 | H1505: =$O$6 -> 88.522826 | I1505: =$O$7 -> 134.88198 | J1505: =$O$9 -> -4.1954743 | K1505: =$O$10 -> -50.554625 | L1505: ='ISC1'!$S$3 -> 26.873763
A1506: 46262 | B1506: =IFERROR(INDEX(_xlfn.STOCKHISTORY("095340", A1506), 2, 2), "") | C1506: ='ISC1'!$L$4 -> 21197058 | D1506: =C1506*N(B1506) -> 0 | E1506: 102000000010 | F1506: =D1506/E1506 -> 0 | G1506: =$O$4 -> 42.163676 | H1506: =$O$6 -> 88.522826 | I1506: =$O$7 -> 134.88198 | J1506: =$O$9 -> -4.1954743 | K1506: =$O$10 -> -50.554625 | L1506: ='ISC1'!$S$3 -> 26.873763
A1507: 46263 | B1507: =IFERROR(INDEX(_xlfn.STOCKHISTORY("095340", A1507), 2, 2), "") | C1507: ='ISC1'!$L$4 -> 21197058 | D1507: =C1507*N(B1507) -> 0 | E1507: 102000000011 | F1507: =D1507/E1507 -> 0 | G1507: =$O$4 -> 42.163676 | H1507: =$O$6 -> 88.522826 | I1507: =$O$7 -> 134.88198 | J1507: =$O$9 -> -4.1954743 | K1507: =$O$10 -> -50.554625 | L1507: ='ISC1'!$S$3 -> 26.873763
... A1681: 46437 | B1681: =IFERROR(INDEX(_xlfn.STOCKHISTORY("095340", A1681), 2, 2), "") | C1681: ='ISC1'!$L$4 -> 21197058 | D1681: =C1681*N(B1681) -> 0 | E1681: 102000000185 | F1681: =D1681/E1681 -> 0 | G1681: =$O$4 -> 42.163676 | H1681: =$O$6 -> 88.522826 | I1681: =$O$7 -> 134.88198 | J1681: =$O$9 -> -4.1954743 | K1681: =$O$10 -> -50.554625 | L1681: ='ISC1'!$S$3 -> 26.873763

Sheet DB하이텍1
A1: DB하이텍POR밴드
B3: 연도 | C3: 2021 | D3: 2022 | E3: 2023 | F3: 2024 | G3: 2025 | H3: 2026(E) | I3: 시가총액 | J3: POR | K3: 현재가 | L3: 발행주식수 | N3: 2027(E) | O3: 459100000000 | P3: 시가총액 | Q3: =K4*L4 -> 4141636777600 | R3: 2027(POR) | S3: =Q3/O3 -> 9.0212084
B4: 영업이익 | C4: 399100000000 | D4: 761900000000 | E4: 265400000000 | F4: 190800000000 | G4: 277300000000 | H4: 366800000000 | I4: =L4*K4 -> 4141636777600 | J4: =I4/H4 -> 11.291267 | K4: 95200 | L4: 43504588

Sheet DB하이텍2
A1: 날짜 | B1: 종가 | C1: 발행주식수 | D1: 시가총액 | E1: 영업이익 | F1: POR | G1: Mean | H1: +1σ | I1: +2σ | J1: -1σ | K1: -2σ | L1: 2027POR
A2: 44200 | B2: 51100 | C2: =DB하이텍1!$L$4 -> 43504588 | D2: =C2*B2 -> 2223084446800 | E2: 399100000000 | F2: =D2/E2 -> 5.5702442 | G2: =$O$4 -> 7.8225362 | H2: =$O$6 -> 11.272246 | I2: =$O$7 -> 14.721956 | J2: =$O$9 -> 4.3728261 | K2: =$O$10 -> 0.92311611 | L2: =DB하이텍1!$S$3 -> 9.0212084 | N2: https://kr.investing.com/equities/dongbu-hitek-historical-data
A3: 44201 | B3: 49900 | C3: =DB하이텍1!$L$4 -> 43504588 | D3: =C3*B3 -> 2170878941200 | E3: 399100000000 | F3: =D3/E3 -> 5.4394361 | G3: =$O$4 -> 7.8225362 | H3: =$O$6 -> 11.272246 | I3: =$O$7 -> 14.721956 | J3: =$O$9 -> 4.3728261 | K3: =$O$10 -> 0.92311611 | L3: =DB하이텍1!$S$3 -> 9.0212084
A4: 44202 | B4: 53600 | C4: =DB하이텍1!$L$4 -> 43504588 | D4: =C4*B4 -> 2331845916800 | E4: 399100000000 | F4: =D4/E4 -> 5.842761 | G4: =$O$4 -> 7.8225362 | H4: =$O$6 -> 11.272246 | I4: =$O$7 -> 14.721956 | J4: =$O$9 -> 4.3728261 | K4: =$O$10 -> 0.92311611 | L4: =DB하이텍1!$S$3 -> 9.0212084 | N4: Mean | O4: =AVERAGE(F2:F1528) -> 7.8225362
A5: 44203 | B5: 54000 | C5: =DB하이텍1!$L$4 -> 43504588 | D5: =C5*B5 -> 2349247752000 | E5: 399100000000 | F5: =D5/E5 -> 5.8863637 | G5: =$O$4 -> 7.8225362 | H5: =$O$6 -> 11.272246 | I5: =$O$7 -> 14.721956 | J5: =$O$9 -> 4.3728261 | K5: =$O$10 -> 0.92311611 | L5: =DB하이텍1!$S$3 -> 9.0212084 | N5: STDEV | O5: =STDEV(F2:F1528) -> 3.44971
A6: 44204 | B6: 54900 | C6: =DB하이텍1!$L$4 -> 43504588 | D6: =C6*B6 -> 2388401881200 | E6: 399100000000 | F6: =D6/E6 -> 5.9844698 | G6: =$O$4 -> 7.8225362 | H6: =$O$6 -> 11.272246 | I6: =$O$7 -> 14.721956 | J6: =$O$9 -> 4.3728261 | K6: =$O$10 -> 0.92311611 | L6: =DB하이텍1!$S$3 -> 9.0212084 | N6: +1σ | O6: =O4+O5 -> 11.272246
A7: 44206 | B7: 54900 | C7: =DB하이텍1!$L$4 -> 43504588 | D7: =C7*B7 -> 2388401881200 | E7: 399100000000 | F7: =D7/E7 -> 5.9844698 | G7: =$O$4 -> 7.8225362 | H7: =$O$6 -> 11.272246 | I7: =$O$7 -> 14.721956 | J7: =$O$9 -> 4.3728261 | K7: =$O$10 -> 0.92311611 | L7: =DB하이텍1!$S$3 -> 9.0212084 | N7: +2σ | O7: =(O5*2)+O4 -> 14.721956
A8: 44207 | B8: 56200 | C8: =DB하이텍1!$L$4 -> 43504588 | D8: =C8*B8 -> 2444957845600 | E8: 399100000000 | F8: =D8/E8 -> 6.1261785 | G8: =$O$4 -> 7.8225362 | H8: =$O$6 -> 11.272246 | I8: =$O$7 -> 14.721956 | J8: =$O$9 -> 4.3728261 | K8: =$O$10 -> 0.92311611 | L8: =DB하이텍1!$S$3 -> 9.0212084 | N8: +3σ | O8: =(O5*3)+O4 -> 18.171666
A9: 44208 | B9: 61900 | C9: =DB하이텍1!$L$4 -> 43504588 | D9: =C9*B9 -> 2692933997200 | E9: 399100000000 | F9: =D9/E9 -> 6.7475169 | G9: =$O$4 -> 7.8225362 | H9: =$O$6 -> 11.272246 | I9: =$O$7 -> 14.721956 | J9: =$O$9 -> 4.3728261 | K9: =$O$10 -> 0.92311611 | L9: =DB하이텍1!$S$3 -> 9.0212084 | N9: -1σ | O9: =O4-O5 -> 4.3728261
A10: 44209 | B10: 59500 | C10: =DB하이텍1!$L$4 -> 43504588 | D10: =C10*B10 -> 2588522986000 | E10: 399100000000 | F10: =D10/E10 -> 6.4859007 | G10: =$O$4 -> 7.8225362 | H10: =$O$6 -> 11.272246 | I10: =$O$7 -> 14.721956 | J10: =$O$9 -> 4.3728261 | K10: =$O$10 -> 0.92311611 | L10: =DB하이텍1!$S$3 -> 9.0212084 | N10: -2σ | O10: =O4-(O5*2) -> 0.92311611
A11: 44210 | B11: 59400 | C11: =DB하이텍1!$L$4 -> 43504588 | D11: =C11*B11 -> 2584172527200 | E11: 399100000000 | F11: =D11/E11 -> 6.4750001 | G11: =$O$4 -> 7.8225362 | H11: =$O$6 -> 11.272246 | I11: =$O$7 -> 14.721956 | J11: =$O$9 -> 4.3728261 | K11: =$O$10 -> 0.92311611 | L11: =DB하이텍1!$S$3 -> 9.0212084 | N11: -3σ | O11: =O4-(O5*3) -> -2.5265939
A12: 44211 | B12: 59900 | C12: =DB하이텍1!$L$4 -> 43504588 | D12: =C12*B12 -> 2605924821200 | E12: 399100000000 | F12: =D12/E12 -> 6.5295034 | G12: =$O$4 -> 7.8225362 | H12: =$O$6 -> 11.272246 | I12: =$O$7 -> 14.721956 | J12: =$O$9 -> 4.3728261 | K12: =$O$10 -> 0.92311611 | L12: =DB하이텍1!$S$3 -> 9.0212084
A13: 44213 | B13: 59900 | C13: =DB하이텍1!$L$4 -> 43504588 | D13: =C13*B13 -> 2605924821200 | E13: 399100000000 | F13: =D13/E13 -> 6.5295034 | G13: =$O$4 -> 7.8225362 | H13: =$O$6 -> 11.272246 | I13: =$O$7 -> 14.721956 | J13: =$O$9 -> 4.3728261 | K13: =$O$10 -> 0.92311611 | L13: =DB하이텍1!$S$3 -> 9.0212084
A14: 44214 | B14: 63500 | C14: =DB하이텍1!$L$4 -> 43504588 | D14: =C14*B14 -> 2762541338000 | E14: 399100000000 | F14: =D14/E14 -> 6.9219277 | G14: =$O$4 -> 7.8225362 | H14: =$O$6 -> 11.272246 | I14: =$O$7 -> 14.721956 | J14: =$O$9 -> 4.3728261 | K14: =$O$10 -> 0.92311611 | L14: =DB하이텍1!$S$3 -> 9.0212084
A15: 44215 | B15: 63400 | C15: =DB하이텍1!$L$4 -> 43504588 | D15: =C15*B15 -> 2758190879200 | E15: 399100000000 | F15: =D15/E15 -> 6.911027 | G15: =$O$4 -> 7.8225362 | H15: =$O$6 -> 11.272246 | I15: =$O$7 -> 14.721956 | J15: =$O$9 -> 4.3728261 | K15: =$O$10 -> 0.92311611 | L15: =DB하이텍1!$S$3 -> 9.0212084
A16: 44216 | B16: 69200 | C16: =DB하이텍1!$L$4 -> 43504588 | D16: =C16*B16 -> 3010517489600 | E16: 399100000000 | F16: =D16/E16 -> 7.5432661 | G16: =$O$4 -> 7.8225362 | H16: =$O$6 -> 11.272246 | I16: =$O$7 -> 14.721956 | J16: =$O$9 -> 4.3728261 | K16: =$O$10 -> 0.92311611 | L16: =DB하이텍1!$S$3 -> 9.0212084
A17: 44217 | B17: 71300 | C17: =DB하이텍1!$L$4 -> 43504588 | D17: =C17*B17 -> 3101877124400 | E17: 399100000000 | F17: =D17/E17 -> 7.7721802 | G17: =$O$4 -> 7.8225362 | H17: =$O$6 -> 11.272246 | I17: =$O$7 -> 14.721956 | J17: =$O$9 -> 4.3728261 | K17: =$O$10 -> 0.92311611 | L17: =DB하이텍1!$S$3 -> 9.0212084
A18: 44218 | B18: 69200 | C18: =DB하이텍1!$L$4 -> 43504588 | D18: =C18*B18 -> 3010517489600 | E18: 399100000000 | F18: =D18/E18 -> 7.5432661 | G18: =$O$4 -> 7.8225362 | H18: =$O$6 -> 11.272246 | I18: =$O$7 -> 14.721956 | J18: =$O$9 -> 4.3728261 | K18: =$O$10 -> 0.92311611 | L18: =DB하이텍1!$S$3 -> 9.0212084
A19: 44220 | B19: 69200 | C19: =DB하이텍1!$L$4 -> 43504588 | D19: =C19*B19 -> 3010517489600 | E19: 399100000000 | F19: =D19/E19 -> 7.5432661 | G19: =$O$4 -> 7.8225362 | H19: =$O$6 -> 11.272246 | I19: =$O$7 -> 14.721956 | J19: =$O$9 -> 4.3728261 | K19: =$O$10 -> 0.92311611 | L19: =DB하이텍1!$S$3 -> 9.0212084
A20: 44221 | B20: 70300 | C20: =DB하이텍1!$L$4 -> 43504588 | D20: =C20*B20 -> 3058372536400 | E20: 399100000000 | F20: =D20/E20 -> 7.6631735 | G20: =$O$4 -> 7.8225362 | H20: =$O$6 -> 11.272246 | I20: =$O$7 -> 14.721956 | J20: =$O$9 -> 4.3728261 | K20: =$O$10 -> 0.92311611 | L20: =DB하이텍1!$S$3 -> 9.0212084
A21: 44222 | B21: 67300 | C21: =DB하이텍1!$L$4 -> 43504588 | D21: =C21*B21 -> 2927858772400 | E21: 399100000000 | F21: =D21/E21 -> 7.3361533 | G21: =$O$4 -> 7.8225362 | H21: =$O$6 -> 11.272246 | I21: =$O$7 -> 14.721956 | J21: =$O$9 -> 4.3728261 | K21: =$O$10 -> 0.92311611 | L21: =DB하이텍1!$S$3 -> 9.0212084
A22: 44223 | B22: 66200 | C22: =DB하이텍1!$L$4 -> 43504588 | D22: =C22*B22 -> 2880003725600 | E22: 399100000000 | F22: =D22/E22 -> 7.2162459 | G22: =$O$4 -> 7.8225362 | H22: =$O$6 -> 11.272246 | I22: =$O$7 -> 14.721956 | J22: =$O$9 -> 4.3728261 | K22: =$O$10 -> 0.92311611 | L22: =DB하이텍1!$S$3 -> 9.0212084
A23: 44224 | B23: 66900 | C23: =DB하이텍1!$L$4 -> 43504588 | D23: =C23*B23 -> 2910456937200 | E23: 399100000000 | F23: =D23/E23 -> 7.2925506 | G23: =$O$4 -> 7.8225362 | H23: =$O$6 -> 11.272246 | I23: =$O$7 -> 14.721956 | J23: =$O$9 -> 4.3728261 | K23: =$O$10 -> 0.92311611 | L23: =DB하이텍1!$S$3 -> 9.0212084
... A1527: 46248 | B1527: 102800 | C1527: =DB하이텍1!$L$4 -> 43504588 | D1527: =C1527*B1527 -> 4472271646400 | E1527: 366800000000 | F1527: =D1527/E1527 -> 12.192671 | G1527: =$O$4 -> 7.8225362 | H1527: =$O$6 -> 11.272246 | I1527: =$O$7 -> 14.721956 | J1527: =$O$9 -> 4.3728261 | K1527: =$O$10 -> 0.92311611 | L1527: =DB하이텍1!$S$3 -> 9.0212084
A1528: 46252 | B1528: =IFERROR(INDEX(_xlfn.STOCKHISTORY("XKRX:000990", A1528), 2, 2), "") -> 97600 | C1528: =DB하이텍1!$L$4 -> 43504588 | D1528: =C1528*N(B1528) -> 4246047788800 | E1528: 366800000000 | F1528: =D1528/E1528 -> 11.575921 | G1528: =$O$4 -> 7.8225362 | H1528: =$O$6 -> 11.272246 | I1528: =$O$7 -> 14.721956 | J1528: =$O$9 -> 4.3728261 | K1528: =$O$10 -> 0.92311611 | L1528: =DB하이텍1!$S$3 -> 9.0212084
A1529: 46253 | B1529: =IFERROR(INDEX(_xlfn.STOCKHISTORY("XKRX:000990", A1529), 2, 2), "") | C1529: =DB하이텍1!$L$4 -> 43504588 | D1529: =C1529*N(B1529) -> 0 | E1529: 366800000001 | F1529: =D1529/E1529 -> 0 | G1529: =$O$4 -> 7.8225362 | H1529: =$O$6 -> 11.272246 | I1529: =$O$7 -> 14.721956 | J1529: =$O$9 -> 4.3728261 | K1529: =$O$10 -> 0.92311611 | L1529: =DB하이텍1!$S$3 -> 9.0212084
A1530: 46254 | B1530: =IFERROR(INDEX(_xlfn.STOCKHISTORY("XKRX:000990", A1530), 2, 2), "") | C1530: =DB하이텍1!$L$4 -> 43504588 | D1530: =C1530*N(B1530) -> 0 | E1530: 366800000002 | F1530: =D1530/E1530 -> 0 | G1530: =$O$4 -> 7.8225362 | H1530: =$O$6 -> 11.272246 | I1530: =$O$7 -> 14.721956 | J1530: =$O$9 -> 4.3728261 | K1530: =$O$10 -> 0.92311611 | L1530: =DB하이텍1!$S$3 -> 9.0212084
A1531: 46255 | B1531: =IFERROR(INDEX(_xlfn.STOCKHISTORY("XKRX:000990", A1531), 2, 2), "") | C1531: =DB하이텍1!$L$4 -> 43504588 | D1531: =C1531*N(B1531) -> 0 | E1531: 366800000003 | F1531: =D1531/E1531 -> 0 | G1531: =$O$4 -> 7.8225362 | H1531: =$O$6 -> 11.272246 | I1531: =$O$7 -> 14.721956 | J1531: =$O$9 -> 4.3728261 | K1531: =$O$10 -> 0.92311611 | L1531: =DB하이텍1!$S$3 -> 9.0212084
A1532: 46256 | B1532: =IFERROR(INDEX(_xlfn.STOCKHISTORY("XKRX:000990", A1532), 2, 2), "") | C1532: =DB하이텍1!$L$4 -> 43504588 | D1532: =C1532*N(B1532) -> 0 | E1532: 366800000004 | F1532: =D1532/E1532 -> 0 | G1532: =$O$4 -> 7.8225362 | H1532: =$O$6 -> 11.272246 | I1532: =$O$7 -> 14.721956 | J1532: =$O$9 -> 4.3728261 | K1532: =$O$10 -> 0.92311611 | L1532: =DB하이텍1!$S$3 -> 9.0212084
A1533: 46257 | B1533: =IFERROR(INDEX(_xlfn.STOCKHISTORY("XKRX:000990", A1533), 2, 2), "") | C1533: =DB하이텍1!$L$4 -> 43504588 | D1533: =C1533*N(B1533) -> 0 | E1533: 366800000005 | F1533: =D1533/E1533 -> 0 | G1533: =$O$4 -> 7.8225362 | H1533: =$O$6 -> 11.272246 | I1533: =$O$7 -> 14.721956 | J1533: =$O$9 -> 4.3728261 | K1533: =$O$10 -> 0.92311611 | L1533: =DB하이텍1!$S$3 -> 9.0212084
